<?xml version="1.0" ?>
<robot name="robob_platform">
  <joint name="robob_platform__leftbackwheel_joint" type="continuous">
    <parent link="robob_platform__base_link"/>
    <child link="robob_platform__left_back_wheel"/>
    <origin rpy="0      1.5707  1.5707" xyz="-0.09  0.09  0.03"/>
    <axis xyz="9.00000000e-05   9.00000000e-05   1.00000000e+00"/>
    <limit effort="0" lower="0" upper="0" velocity="0"/>
  </joint>
  <joint name="robob_platform__rightbackwheel_joint" type="continuous">
    <parent link="robob_platform__base_link"/>
    <child link="robob_platform__right_back_wheel"/>
    <origin rpy="0      1.5707  1.5707" xyz="-0.09 -0.09  0.03"/>
    <axis xyz="9.00000000e-05   9.00000000e-05   1.00000000e+00"/>
    <limit effort="0" lower="0" upper="0" velocity="0"/>
  </joint>
  <joint name="robob_platform__leftfrontwheel_joint" type="continuous">
    <parent link="robob_platform__base_link"/>
    <child link="robob_platform__left_front_wheel"/>
    <origin rpy="0      1.5707  1.5707" xyz="0.09  0.09  0.03"/>
    <axis xyz="9.00000000e-05   9.00000000e-05   1.00000000e+00"/>
    <limit effort="0" lower="0" upper="0" velocity="0"/>
  </joint>
  <joint name="robob_platform__rightfrontwheel_joint" type="continuous">
    <parent link="robob_platform__base_link"/>
    <child link="robob_platform__right_front_wheel"/>
    <origin rpy="0      1.5707  1.5707" xyz="0.09 -0.09  0.03"/>
    <axis xyz="9.00000000e-05   9.00000000e-05   1.00000000e+00"/>
    <limit effort="0" lower="0" upper="0" velocity="0"/>
  </joint>
  <link name="robob_platform__base_link">
    <inertial>
      <mass value="0"/>
      <origin rpy="0  0  0" xyz="0  0  0"/>
      <inertia ixx="0" ixy="0" ixz="0" iyy="0" iyz="0" izz="0"/>
    </inertial>
    <collision name="robob_platform__platform_link_collision">
      <origin rpy="0  0  0" xyz="0  0  0"/>
      <geometry>
        <mesh filename="package://robot_description/models/robob/robob_platform.dae" scale="1.0 1.0 1.0"/>
      </geometry>
    </collision>
    <visual name="robob_platform__platform_link_visual">
      <origin rpy="0  0  0" xyz="0  0  0"/>
      <geometry>
        <mesh filename="package://robot_description/models/robob/robob_platform.dae" scale="1.0 1.0 1.0"/>
      </geometry>
    </visual>
  </link>
  <link name="robob_platform__left_front_wheel">
    <inertial>
      <mass value="0"/>
      <origin rpy="0  0  0" xyz="0  0  0"/>
      <inertia ixx="0" ixy="0" ixz="0" iyy="0" iyz="0" izz="0"/>
    </inertial>
    <collision name="robob_platform__left_front_wheel_collision">
      <origin rpy="0  0  0" xyz="0  0  0"/>
      <geometry>
        <cylinder length=".02" radius=".03"/>
      </geometry>
    </collision>
    <visual name="robob_platform__left_front_wheel_visual">
      <origin rpy="0  0  0" xyz="0  0  0"/>
      <geometry>
        <cylinder length=".02" radius=".03"/>
      </geometry>
    </visual>
  </link>
  <link name="robob_platform__right_front_wheel">
    <inertial>
      <mass value="0"/>
      <origin rpy="0  0  0" xyz="0  0  0"/>
      <inertia ixx="0" ixy="0" ixz="0" iyy="0" iyz="0" izz="0"/>
    </inertial>
    <collision name="robob_platform__right_front_wheel_collision">
      <origin rpy="0  0  0" xyz="0  0  0"/>
      <geometry>
        <cylinder length=".02" radius=".03"/>
      </geometry>
    </collision>
    <visual name="robob_platform__right_front_wheel_visual">
      <origin rpy="0  0  0" xyz="0  0  0"/>
      <geometry>
        <cylinder length=".02" radius=".03"/>
      </geometry>
    </visual>
  </link>
  <link name="robob_platform__right_back_wheel">
    <inertial>
      <mass value="0"/>
      <origin rpy="0  0  0" xyz="0  0  0"/>
      <inertia ixx="0" ixy="0" ixz="0" iyy="0" iyz="0" izz="0"/>
    </inertial>
    <collision name="robob_platform__right_back_wheel_collision">
      <origin rpy="0  0  0" xyz="0  0  0"/>
      <geometry>
        <cylinder length=".02" radius=".03"/>
      </geometry>
    </collision>
    <visual name="robob_platform__right_back_wheelvisual">
      <origin rpy="0  0  0" xyz="0  0  0"/>
      <geometry>
        <cylinder length=".02" radius=".03"/>
      </geometry>
    </visual>
  </link>
  <link name="robob_platform__left_back_wheel">
    <inertial>
      <mass value="0"/>
      <origin rpy="0  0  0" xyz="0  0  0"/>
      <inertia ixx="0" ixy="0" ixz="0" iyy="0" iyz="0" izz="0"/>
    </inertial>
    <collision name="robob_platform__left_back_wheel_collision">
      <origin rpy="0  0  0" xyz="0  0  0"/>
      <geometry>
        <cylinder length=".02" radius=".03"/>
      </geometry>
    </collision>
    <visual name="robob_platform__left_back_wheel_visual">
      <origin rpy="0  0  0" xyz="0  0  0"/>
      <geometry>
        <cylinder length=".02" radius=".03"/>
      </geometry>
    </visual>
  </link>
</robot>
